<?xml version="1.0" ?>
<robot name="nimbro_op2x" xmlns:xacro="http://www.ros.org/wiki/xacro">
	<xacro:property name="mypi" value="3.1415926535897931" />
	<xacro:property name="deg" value="${mypi/180}" />

		<!-- Materials -->
		<material name="black">
			<color rgba="0.1 0.1 0.1 1" />
		</material>
		<material name="white">
			<color rgba="0.8 0.8 0.8 1" />
		</material>
		<material name="clear">
			<color rgba="1.0 1.0 1.0 0.0" />
		</material>
		<material name="orange">
			<color rgba="${255/255} ${108/255} ${10/255} 1.0" />
		</material>

		<!-- Joints and links -->
		<link name="trunk_link">
			<inertial>
				<origin xyz="0 0 0" rpy="0 0 0" />
				<mass value="5.06692801" />
				<inertia ixx="0.18042907" ixy="-0.00003477" ixz="0.00412903"
				iyy="0.16069639" iyz="-0.00149697" izz="0.05070835" />
			</inertial>
			<visual>
				<origin xyz="0 0 0" rpy="0 0 0 " />
				<geometry>
					<mesh filename="package://nimbro_op_model/mesh/nimbro_op2x_hull/trunk_link.STL" />
				</geometry>
				<material name="white" />
			</visual>
			<collision>
				<origin xyz="0 0 0" rpy="0 0 0" />
				<geometry>
					<mesh filename="package://nimbro_op_model/mesh/nimbro_op2x_hull/trunk_link.STL" />
				</geometry>
			</collision>
		</link>
		<link name="right_hip_yaw_link">
			<inertial>
				<origin xyz="0 0 0" rpy="0 0 0" />
				<mass value="0.31538736" />
				<inertia ixx="0.00083031" ixy="0.00000000" ixz="0.00000087"
				iyy="0.00132167" iyz="0.00000000" izz="0.00121851" />
			</inertial>
			<visual>
				<origin xyz="0 0 0" rpy="0 0 0" />
				<geometry>
					<mesh filename="package://nimbro_op_model/mesh/nimbro_op2x_hull/hip_yaw_link.STL" />
				</geometry>
				<material name="white" />
			</visual>
			<collision>
				<origin xyz="0 0 0" rpy="0 0 0" />
				<geometry>
					<mesh filename="package://nimbro_op_model/mesh/nimbro_op2x_hull/hip_yaw_link.STL" />
				</geometry>
			</collision>
		</link>
		<joint name="right_hip_yaw" type="continuous">
			<origin xyz="0 -0.08 0.0005" rpy="0 0 0" />
			<parent link="trunk_link" />
			<child link="right_hip_yaw_link" />
			<axis xyz="0 0 1" />
		</joint>
		<link name="right_hip_roll_link">
			<inertial>
				<origin xyz="0 0 0" rpy="0 0 0" />
				<mass value="0.52680550" />
				<inertia ixx="0.00120200" ixy="0.00000000" ixz="0.00001968"
				iyy="0.00166590" iyz="-0.00000740" izz="0.00112573" />
			</inertial>
			<visual>
				<origin xyz="0 0 0" rpy="0 0 0" />
				<geometry>
					<mesh filename="package://nimbro_op_model/mesh/nimbro_op2x_hull/right_hip_link.STL" />
				</geometry>
				<material name="white" />
			</visual>
			<collision>
				<origin xyz="0 0 0" rpy="0 0 0" />
				<geometry>
					<mesh filename="package://nimbro_op_model/mesh/nimbro_op2x_hull/right_hip_link.STL" />
				</geometry>
			</collision>
		</link>
		<joint name="right_hip_roll" type="continuous">
			<origin xyz="0 0 -0.061" rpy="0 0 0" />
			<parent link="right_hip_yaw_link" />
			<child link="right_hip_roll_link" />
			<axis xyz="1 0 0" />
		</joint>
		<link name="right_thigh_link">
			<inertial>
				<origin xyz="0 0 0" rpy="0 0 0" />
				<mass value="0.55499173" />
				<inertia ixx="0.01456501" ixy="-0.00000047" ixz="0.00009111"
				iyy="0.01458714" iyz="0.00002339" izz="0.00214713" />
			</inertial>
			<visual>
				<origin xyz="0 0 0" rpy="0 0 0" />
				<geometry>
					<mesh filename="package://nimbro_op_model/mesh/nimbro_op2x_hull/right_thigh_link.STL" />
				</geometry>
				<material name="white" />
			</visual>
			<collision>
				<origin xyz="0 0 0" rpy="0 0 0" />
				<geometry>
					<mesh filename="package://nimbro_op_model/mesh/nimbro_op2x_hull/right_thigh_link.STL" />
				</geometry>
			</collision>
		</link>
		<joint name="right_hip_pitch" type="continuous">
			<origin xyz="0 0 -0.03345" rpy="0 0 0" />
			<parent link="right_hip_roll_link" />
			<child link="right_thigh_link" />
			<axis xyz="0 1 0" />
		</joint>
		<link name="right_shank_link">
			<inertial>
				<origin xyz="0 0 0" rpy="0 0 0" />
				<mass value="1.83365379" />
				<inertia ixx="0.02014567" ixy="-0.00000142" ixz="-0.00052860"
				iyy="0.02047566" iyz="0.00002624" izz="0.00481117" />
			</inertial>
			<visual>
				<origin xyz="0 0 0" rpy="0 0 0" />
				<geometry>
					<mesh filename="package://nimbro_op_model/mesh/nimbro_op2x_hull/right_shank_link.STL" />
				</geometry>
				<material name="white" />
			</visual>
			<collision>
				<origin xyz="0 0 0" rpy="0 0 0" />
				<geometry>
					<mesh filename="package://nimbro_op_model/mesh/nimbro_op2x_hull/right_shank_link.STL" />
				</geometry>
			</collision>
		</link>
		<joint name="right_knee_pitch" type="continuous">
			<origin xyz="0 0 -0.29835" rpy="0 0 0" />
			<parent link="right_thigh_link" />
			<child link="right_shank_link" />
			<axis xyz="0 1 0" />
		</joint>
		<link name="right_ankle_link">
			<inertial>
				<origin xyz="0 0 0" rpy="0 0 0" />
				<mass value="0.52680550" />
				<inertia ixx="0.00054388" ixy="0.00000000" ixz="-0.00001644"
				iyy="0.00100778" iyz="-0.00000164" izz="0.00112573" />
			</inertial>
			<visual>
				<origin xyz="0 0 0" rpy="0 0 0" />
				<geometry>
					<mesh filename="package://nimbro_op_model/mesh/nimbro_op2x_hull/right_ankle_link.STL" />
				</geometry>
				<material name="white" />
			</visual>
			<collision>
				<origin xyz="0 0 0" rpy="0 0 0" />
				<geometry>
					<mesh filename="package://nimbro_op_model/mesh/nimbro_op2x_hull/right_ankle_link.STL" />
				</geometry>
			</collision>
		</link>
		<joint name="right_ankle_pitch" type="continuous">
			<origin xyz="0 0 -0.29835" rpy="0 0 0" />
			<parent link="right_shank_link" />
			<child link="right_ankle_link" />
			<axis xyz="0 1 0" />
		</joint>
		<link name="right_foot_link">
			<inertial>
				<origin xyz="0 0 0" rpy="0 0 0" />
				<mass value="0.49970531" />
				<inertia ixx="0.00157166" ixy="-0.00008685" ixz="-0.00064756"
				iyy="0.00509988" iyz="0.00005307" izz="0.00557515" />
			</inertial>
			<visual>
				<origin xyz="0 0 0" rpy="0 0 0" />
				<geometry>
					<mesh filename="package://nimbro_op_model/mesh/nimbro_op2x_hull/right_foot_link.STL" />
				</geometry>
				<material name="white" />
			</visual>
			<collision>
				<origin xyz="0 0 0" rpy="0 0 0" />
				<geometry>
					<mesh filename="package://nimbro_op_model/mesh/nimbro_op2x_hull/right_foot_link.STL" />
				</geometry>
			</collision>
		</link>
		<joint name="right_ankle_roll" type="continuous">
			<origin xyz="0 0 -0.03345" rpy="0 0 0" />
			<parent link="right_ankle_link" />
			<child link="right_foot_link" />
			<axis xyz="1 0 0" />
		</joint>
		<link name="right_foot_plane_link">
		</link>
		<joint name="right_foot_plane_joint" type="fixed">
			<origin xyz="0.04562 -0.005 -0.055" rpy="0 0 0" />
			<parent link="right_foot_link" />
			<child link="right_foot_plane_link" />
		</joint>

		<link name="left_hip_yaw_link">
			<inertial>
				<origin xyz="0 0 0" rpy="0 0 0" />
				<mass value="0.31538736" />
				<inertia ixx="0.00083031" ixy="0.00000000" ixz="0.00000087"
				iyy="0.00132167" iyz="0.00000000" izz="0.00121851" />
			</inertial>
			<visual>
				<origin xyz="0 0 0" rpy="0 0 0" />
				<geometry>
					<mesh filename="package://nimbro_op_model/mesh/nimbro_op2x_hull/hip_yaw_link.STL" />
				</geometry>
				<material name="white" />
			</visual>
			<collision>
				<origin xyz="0 0 0" rpy="0 0 0" />
				<geometry>
					<mesh filename="package://nimbro_op_model/mesh/nimbro_op2x_hull/hip_yaw_link.STL" />
				</geometry>
			</collision>
		</link>
		<joint name="left_hip_yaw" type="continuous">
			<origin xyz="0 0.08 0.0005" rpy="0 0 0" />
			<parent link="trunk_link" />
			<child link="left_hip_yaw_link" />
			<axis xyz="0 0 1" />
		</joint>
		<link name="left_hip_roll_link">
			<inertial>
				<origin xyz="0 0 0" rpy="0 0 0" />
				<mass value="0.52680550" />
				<inertia ixx="0.00120200" ixy="0.00000008" ixz="0.00001968"
				iyy="0.00166590" iyz="0.00000739" izz="0.00112573" />
			</inertial>
			<visual>
				<origin xyz="0 0 0" rpy="0 0 0" />
				<geometry>
					<mesh filename="package://nimbro_op_model/mesh/nimbro_op2x_hull/left_hip_link.STL" />
				</geometry>
				<material name="white" />
			</visual>
			<collision>
				<origin xyz="0 0 0" rpy="0 0 0" />
				<geometry>
					<mesh filename="package://nimbro_op_model/mesh/nimbro_op2x_hull/left_hip_link.STL" />
				</geometry>
			</collision>
		</link>
		<joint name="left_hip_roll" type="continuous">
			<origin xyz="0 0 -0.061" rpy="0 0 0" />
			<parent link="left_hip_yaw_link" />
			<child link="left_hip_roll_link" />
			<axis xyz="1 0 0" />
		</joint>
		<link name="left_thigh_link">
			<inertial>
				<origin xyz="0 0 0" rpy="0 0 0" />
				<mass value="0.55499173" />
				<inertia ixx="0.01456501" ixy="-0.00000047" ixz="0.00009111"
				iyy="0.01458714" iyz="0.00002339" izz="0.00214713" />
			</inertial>
			<visual>
				<origin xyz="0 0 0" rpy="0 0 0" />
				<geometry>
					<mesh filename="package://nimbro_op_model/mesh/nimbro_op2x_hull/left_thigh_link.STL" />
				</geometry>
				<material name="white" />
			</visual>
			<collision>
				<origin xyz="0 0 0" rpy="0 0 0" />
				<geometry>
					<mesh filename="package://nimbro_op_model/mesh/nimbro_op2x_hull/left_thigh_link.STL" />
				</geometry>
			</collision>
		</link>
		<joint name="left_hip_pitch" type="continuous">
			<origin xyz="0 0 -0.03345" rpy="0 0 0" />
			<parent link="left_hip_roll_link" />
			<child link="left_thigh_link" />
			<axis xyz="0 1 0" />
		</joint>
		<link name="left_shank_link">
			<inertial>
				<origin xyz="0 0 0" rpy="0 0 0" />
				<mass value="1.83365379" />
				<inertia ixx="0.02014567" ixy="-0.00000142" ixz="-0.00052860"
				iyy="0.02047566" iyz="0.00002624" izz="0.00481117" />
			</inertial>
			<visual>
				<origin xyz="0 0 0" rpy="0 0 0" />
				<geometry>
					<mesh filename="package://nimbro_op_model/mesh/nimbro_op2x_hull/left_shank_link.STL" />
				</geometry>
				<material name="white" />
			</visual>
			<collision>
				<origin xyz="0 0 0" rpy="0 0 0" />
				<geometry>
					<mesh filename="package://nimbro_op_model/mesh/nimbro_op2x_hull/left_shank_link.STL" />
				</geometry>
			</collision>
		</link>
		<joint name="left_knee_pitch" type="continuous">
			<origin xyz="0 0 -0.29835" rpy="0 0 0" />
			<parent link="left_thigh_link" />
			<child link="left_shank_link" />
			<axis xyz="0 1 0" />
		</joint>
		<link name="left_ankle_link">
			<inertial>
				<origin xyz="0 0 0" rpy="0 0 0" />
				<mass value="0.52680550" />
				<inertia ixx="0.00054388" ixy="-0.00000008" ixz="-0.00001644"
				iyy="0.00100778" iyz="0.00000167" izz="0.00112573" />
			</inertial>
			<visual>
				<origin xyz="0 0 0" rpy="0 0 0" />
				<geometry>
					<mesh filename="package://nimbro_op_model/mesh/nimbro_op2x_hull/left_ankle_link.STL" />
				</geometry>
				<material name="white" />
			</visual>
			<collision>
				<origin xyz="0 0 0" rpy="0 0 0" />
				<geometry>
					<mesh filename="package://nimbro_op_model/mesh/nimbro_op2x_hull/left_ankle_link.STL" />
				</geometry>
			</collision>
		</link>
		<joint name="left_ankle_pitch" type="continuous">
			<origin xyz="0 0 -0.29835" rpy="0 0 0" />
			<parent link="left_shank_link" />
			<child link="left_ankle_link" />
			<axis xyz="0 1 0" />
		</joint>
		<link name="left_foot_link">
			<inertial>
				<origin xyz="0 0 0" rpy="0 0 0" />
				<mass value="0.49972267" />
				<inertia ixx="0.00157170" ixy="0.00008675" ixz="-0.00064765"
				iyy="0.00510038" iyz="-0.00005304" izz="0.00557564" />
			</inertial>
			<visual>
				<origin xyz="0 0 0" rpy="0 0 0" />
				<geometry>
					<mesh filename="package://nimbro_op_model/mesh/nimbro_op2x_hull/left_foot_link.STL" />
				</geometry>
				<material name="white" />
			</visual>
			<collision>
				<origin xyz="0 0 0" rpy="0 0 0" />
				<geometry>
					<mesh filename="package://nimbro_op_model/mesh/nimbro_op2x_hull/left_foot_link.STL" />
				</geometry>
			</collision>
		</link>
		<joint name="left_ankle_roll" type="continuous">
			<origin xyz="0 0 -0.03345" rpy="0 0 0" />
			<parent link="left_ankle_link" />
			<child link="left_foot_link" />
			<axis xyz="1 0 0" />
		</joint>
		<link name="left_foot_plane_link">
		</link>
		<joint name="left_foot_plane_joint" type="fixed">
			<origin xyz="0.04562 0.005 -0.055" rpy="0 0 0" />
			<parent link="left_foot_link" />
			<child link="left_foot_plane_link" />
		</joint>

		<link name="right_shoulder_pitch_link">
			<inertial>
				<origin xyz="0 0 0" rpy="0 0 0" />
				<mass value="0.15970499" />
				<inertia ixx="0.00030253" ixy="-0.00000407" ixz="0.00000011"
				iyy="0.00024077" iyz="-0.00003234" izz="0.00035553" />
			</inertial>
			<visual>
				<origin xyz="0 0 0" rpy="0 0 0" />
				<geometry>
					<mesh filename="package://nimbro_op_model/mesh/nimbro_op2x_hull/right_shoulder_link.STL" />
				</geometry>
				<material name="white" />
			</visual>
			<collision>
				<origin xyz="0 0 0" rpy="0 0 0" />
				<geometry>
					<mesh filename="package://nimbro_op_model/mesh/nimbro_op2x_hull/right_shoulder_link.STL" />
				</geometry>
			</collision>
		</link>
		<joint name="right_shoulder_pitch" type="continuous">
			<origin xyz="0 -0.1498 0.236" rpy="0 0 0" />
			<parent link="trunk_link" />
			<child link="right_shoulder_pitch_link" />
			<axis xyz="0 1 0" />
		</joint>
		<link name="right_upper_arm_link">
			<inertial>
				<origin xyz="0 0 0" rpy="0 0 0" />
				<mass value="0.52300771" />
				<inertia ixx="0.00862891" ixy="-0.00000237" ixz="-0.00039851"
				iyy="0.00859246" iyz="0.00002156" izz="0.00061847" />
			</inertial>
			<visual>
				<origin xyz="0 0 0" rpy="0 0 0" />
				<geometry>
					<mesh filename="package://nimbro_op_model/mesh/nimbro_op2x_hull/right_upper_arm_link.STL" />
				</geometry>
				<material name="white" />
			</visual>
			<collision>
				<origin xyz="0 0 0" rpy="0 0 0" />
				<geometry>
					<mesh filename="package://nimbro_op_model/mesh/nimbro_op2x_hull/right_upper_arm_link.STL" />
				</geometry>
			</collision>
		</link>
		<joint name="right_shoulder_roll" type="continuous">
			<origin xyz="0 -0.05575 -0.015" rpy="0 0 0" />
			<parent link="right_shoulder_pitch_link" />
			<child link="right_upper_arm_link" />
			<axis xyz="1 0 0" />
		</joint>
		<link name="right_lower_arm_link">
			<inertial>
				<origin xyz="0 0 0" rpy="0 0 0" />
				<mass value="0.47523964" />
				<inertia ixx="0.00852265" ixy="0.00000000" ixz="-0.00000004"
				iyy="0.00849800" iyz="0.00026661" izz="0.00044576" />
			</inertial>
			<visual>
				<origin xyz="0 0 0" rpy="0 0 0" />
				<geometry>
					<mesh filename="package://nimbro_op_model/mesh/nimbro_op2x_hull/right_lower_arm_link.STL" />
				</geometry>
				<material name="white" />
			</visual>
			<collision>
				<origin xyz="0 0 0" rpy="0 0 0" />
				<geometry>
					<mesh filename="package://nimbro_op_model/mesh/nimbro_op2x_hull/right_lower_arm_link.STL" />
				</geometry>
			</collision>
		</link>
		<joint name="right_elbow_pitch" type="continuous">
			<origin xyz="0.04033 0 -0.24891" rpy="0 0 0" />
			<parent link="right_upper_arm_link" />
			<child link="right_lower_arm_link" />
			<axis xyz="0 1 0" />
		</joint>
		<link name="left_shoulder_pitch_link">
			<inertial>
				<origin xyz="0 0 0" rpy="0 0 0" />
				<mass value="0.15970410" />
				<inertia ixx="0.00030253" ixy="0.00000408" ixz="0.00000011"
				iyy="0.00024078" iyz="0.00003234" izz="0.00035553" />
			</inertial>
			<visual>
				<origin xyz="0 0 0" rpy="0 0 0" />
				<geometry>
					<mesh filename="package://nimbro_op_model/mesh/nimbro_op2x_hull/left_shoulder_link.STL" />
				</geometry>
				<material name="white" />
			</visual>
			<collision>
				<origin xyz="0 0 0" rpy="0 0 0" />
				<geometry>
					<mesh filename="package://nimbro_op_model/mesh/nimbro_op2x_hull/left_shoulder_link.STL" />
				</geometry>
			</collision>
		</link>
		<joint name="left_shoulder_pitch" type="continuous">
			<origin xyz="0 0.1498 0.236" rpy="0 0 0" />
			<parent link="trunk_link" />
			<child link="left_shoulder_pitch_link" />
			<axis xyz="0 1 0" />
		</joint>
		<link name="left_upper_arm_link">
			<inertial>
				<origin xyz="0 0 0" rpy="0 0 0" />
				<mass value="0.52303666" />
				<inertia ixx="0.00862898" ixy="0.00000234" ixz="-0.00037949"
				iyy="0.00858971" iyz="-0.00002155" izz="0.00061569" />
			</inertial>
			<visual>
				<origin xyz="0 0 0" rpy="0 0 0" />
				<geometry>
					<mesh filename="package://nimbro_op_model/mesh/nimbro_op2x_hull/left_upper_arm_link.STL" />
				</geometry>
				<material name="white" />
			</visual>
			<collision>
				<origin xyz="0 0 0" rpy="0 0 0" />
				<geometry>
					<mesh filename="package://nimbro_op_model/mesh/nimbro_op2x_hull/left_upper_arm_link.STL" />
				</geometry>
			</collision>
		</link>
		<joint name="left_shoulder_roll" type="continuous">
			<origin xyz="0 0.05575 -0.015" rpy="0 0 0" />
			<parent link="left_shoulder_pitch_link" />
			<child link="left_upper_arm_link" />
			<axis xyz="1 0 0" />
		</joint>
		<link name="left_lower_arm_link">
			<inertial>
				<origin xyz="0 0 0" rpy="0 0 0" />
				<mass value="0.47523964" />
				<inertia ixx="0.00852159" ixy="0.00000000" ixz="0.00000004"
				iyy="0.00849800" iyz="-0.00025811" izz="0.00044471" />
			</inertial>
			<visual>
				<origin xyz="0 0 0" rpy="0 0 0" />
				<geometry>
					<mesh filename="package://nimbro_op_model/mesh/nimbro_op2x_hull/left_lower_arm_link.STL" />
				</geometry>
				<material name="white" />
			</visual>
			<collision>
				<origin xyz="0 0 0" rpy="0 0 0" />
				<geometry>
					<mesh filename="package://nimbro_op_model/mesh/nimbro_op2x_hull/left_lower_arm_link.STL" />
				</geometry>
			</collision>
		</link>
		<joint name="left_elbow_pitch" type="continuous">
			<origin xyz="0.04033 0 -0.24891" rpy="0 0 0" />
			<parent link="left_upper_arm_link" />
			<child link="left_lower_arm_link" />
			<axis xyz="0 1 0" />
		</joint>
		<link name="neck_link">
			<inertial>
				<origin xyz="0 0 0" rpy="0 0 0" />
				<mass value="0.19581279" />
				<inertia ixx="0.00030225" ixy="0.00000000" ixz="-0.00001219"
				iyy="0.00028951" iyz="0.00000473" izz="0.00006618" />
			</inertial>
			<visual>
				<origin xyz="0 0 0" rpy="0 0 0" />
				<geometry>
					<mesh filename="package://nimbro_op_model/mesh/nimbro_op2x_hull/neck_link.STL" />
				</geometry>
				<material name="black" />
			</visual>
			<collision>
				<origin xyz="0 0 0" rpy="0 0 0" />
				<geometry>
					<mesh filename="package://nimbro_op_model/mesh/nimbro_op2x_hull/neck_link.STL" />
				</geometry>
			</collision>
		</link>
		<joint name="neck_yaw" type="continuous">
			<origin xyz="0.04 0 0.3098" rpy="0 0 0" />
			<parent link="trunk_link" />
			<child link="neck_link" />
			<axis xyz="0 0 1" />
		</joint>
		<link name="head_link">
			<inertial>
				<origin xyz="0 0 0" rpy="0 0 0" />
				<mass value="0.52270194" />
				<inertia ixx="0.00594799" ixy="-0.00000704" ixz="-0.00027581"
				iyy="0.00657505" iyz="-0.00002352" izz="0.00294225" />
			</inertial>
			<visual>
				<origin xyz="0 0 0" rpy="0 0 0" />
				<geometry>
					<mesh filename="package://nimbro_op_model/mesh/nimbro_op2x_hull/head_link.STL" />
				</geometry>
				<material name="white" />
			</visual>
			<collision>
				<origin xyz="0 0 0" rpy="0 0 0" />
				<geometry>
					<mesh filename="package://nimbro_op_model/mesh/nimbro_op2x_hull/head_link.STL" />
				</geometry>
			</collision>
		</link>
		<joint name="head_pitch" type="continuous">
			<origin xyz="0 0 0.04975" rpy="0 0 0" />
			<parent link="neck_link" />
			<child link="head_link" />
			<axis xyz="0 1 0" />
		</joint>
		<link name="camera_optical">
		</link>
		<joint name="camera_joint" type="fixed">
			<origin xyz="0.04488 -0.0375 0.08231" rpy="${-100*deg} 0 ${-90*deg}" />
			<parent link="head_link" />
			<child link="camera_optical" />
			<axis xyz="0 0 0" />
		</joint>



		<!-- Parallel Kinematics visuals only, begin in hip rolls-->
		<!-- Right Leg-->




		<joint name="parallel_right_thigh_pitch" type="continuous">
			<origin xyz="0.0355 0 -0.01955" rpy="0 0 0" />
			<parent link="right_hip_roll_link" />
			<child link="parallel_right_thigh_front_link" />
			<axis xyz="0 1 0" />
		</joint>
		<link name="parallel_right_thigh_front_link">
			<visual>
				<origin xyz="0 0 0" rpy="0 0 0" />
				<geometry>
					<mesh filename="package://nimbro_op_model/mesh/nimbro_op2x_hull/thigh_front_link.STL" />
				</geometry>
				<material name="white" />
			</visual>
		</link>
		<joint name="parallel_right_thigh_pitch_mimic1" type="continuous">
			<origin xyz="0 0 -0.26" rpy="0 0 0" />
			<parent link="parallel_right_thigh_front_link" />
			<child link="parallel_right_knee_front_link" />
			<axis xyz="0 1 0" />
			<mimic joint="parallel_right_thigh_pitch" multiplier="-1" offset="0" />
		</joint>
		<link name="parallel_right_knee_front_link">
			<visual>
				<origin xyz="0 0 0" rpy="0 0 0" />
				<geometry>
					<mesh filename="package://nimbro_op_model/mesh/nimbro_op2x_hull/knee_link.STL" />
				</geometry>
				<material name="white" />
			</visual>
		</link>

		<joint name="parallel_right_shank_pitch" type="continuous">
			<origin xyz="0 0 -0.1045" rpy="0 0 0" />
			<parent link="parallel_right_knee_front_link" />
			<child link="parallel_right_shank_front_link" />
			<axis xyz="0 1 0" />
		</joint>
		<link name="parallel_right_shank_front_link">
			<visual>
				<origin xyz="0 0 0" rpy="0 0 0" />
				<geometry>
					<mesh filename="package://nimbro_op_model/mesh/nimbro_op2x_hull/shank_front_link.STL" />
				</geometry>
				<material name="white" />
			</visual>
		</link>
		<joint name="parallel_right_shank_pitch_mimic1" type="continuous">
			<origin xyz="0 0 -0.26" rpy="0 0 0" />
			<parent link="parallel_right_shank_front_link" />
			<child link="parallel_right_ankle_link" />
			<axis xyz="0 1 0" />
			<mimic joint="parallel_right_shank_pitch" multiplier="-1" offset="0" />
		</joint>
		<link name="parallel_right_ankle_link">
			<visual>
				<origin xyz="-0.03345 0 0.0139" rpy="0 0 0" />
				<geometry>
					<mesh filename="package://nimbro_op_model/mesh/nimbro_op2x_hull/right_ankle_link.STL" />
				</geometry>
				<material name="white" />
			</visual>
		</link>
		<joint name="parallel_right_ankle_roll" type="continuous">
			<origin xyz="-0.03345 0 -0.01955" rpy="0 0 0" />
			<parent link="parallel_right_ankle_link" />
			<child link="parallel_right_foot_link" />
			<axis xyz="1 0 0" />
		</joint>
		<link name="parallel_right_foot_link">
			<visual>
				<origin xyz="0 0 0" rpy="0 0 0" />
				<geometry>
					<mesh filename="package://nimbro_op_model/mesh/nimbro_op2x_hull/right_foot_link.STL" />
				</geometry>
				<material name="white" />
			</visual>
		</link>
		<joint name="parallel_right_foot_plane_joint" type="fixed">
			<origin xyz="0.04562 -0.005 -0.055" rpy="0 0 0" />
			<parent link="parallel_right_foot_link" />
			<child link="parallel_right_foot_plane_link" />
		</joint>
		<link name="parallel_right_foot_plane_link">
		</link>

		<!-- back chain-->

		<joint name="parallel_right_thigh_pitch_mimic2" type="continuous">
			<origin xyz="-0.036 0 -0.04755" rpy="0 0 0" />
			<parent link="right_hip_roll_link" />
			<child link="parallel_right_thigh_back_link" />
			<axis xyz="0 1 0" />
			<mimic joint="parallel_right_thigh_pitch" multiplier="1" offset="0" />
		</joint>
		<link name="parallel_right_thigh_back_link">
			<visual>
				<origin xyz="0 0 0" rpy="0 0 0" />
				<geometry>
					<mesh filename="package://nimbro_op_model/mesh/nimbro_op2x_hull/thigh_back_link.STL" />
				</geometry>
				<material name="white" />
			</visual>
		</link>
		<joint name="parallel_right_thigh_pitch_mimic3" type="continuous">
			<origin xyz="0 0 -0.26" rpy="0 0 0" />
			<parent link="parallel_right_thigh_back_link" />
			<child link="parallel_right_knee_back_link" />
			<axis xyz="0 1 0" />
			<mimic joint="parallel_right_thigh_pitch" multiplier="-1" offset="0" />
		</joint>
		<link name="parallel_right_knee_back_link">
		</link>

		<joint name="parallel_right_shank_pitch_mimic2" type="continuous">
			<origin xyz="0 0 -0.0485" rpy="0 0 0" />
			<parent link="parallel_right_knee_back_link" />
			<child link="parallel_right_shank_back_link" />
			<axis xyz="0 1 0" />
			<mimic joint="parallel_right_shank_pitch" multiplier="1" offset="0" />
		</joint>
		<link name="parallel_right_shank_back_link">
			<visual>
				<origin xyz="0 0 0" rpy="0 0 0" />
				<geometry>
					<mesh filename="package://nimbro_op_model/mesh/nimbro_op2x_hull/shank_back_link.STL" />
				</geometry>
				<material name="white" />
			</visual>
		</link>

		<!-- Left Leg-->



		<joint name="parallel_left_thigh_pitch" type="continuous">
			<origin xyz="0.0355 0 -0.01955" rpy="0 0 0" />
			<parent link="left_hip_roll_link" />
			<child link="parallel_left_thigh_front_link" />
			<axis xyz="0 1 0" />
		</joint>
		<link name="parallel_left_thigh_front_link">
			<visual>
				<origin xyz="0 0 0" rpy="0 0 0" />
				<geometry>
					<mesh filename="package://nimbro_op_model/mesh/nimbro_op2x_hull/thigh_front_link.STL" />
				</geometry>
				<material name="white" />
			</visual>
		</link>
		<joint name="parallel_left_thigh_pitch_mimic1" type="continuous">
			<origin xyz="0 0 -0.26" rpy="0 0 0" />
			<parent link="parallel_left_thigh_front_link" />
			<child link="parallel_left_knee_front_link" />
			<axis xyz="0 1 0" />
			<mimic joint="parallel_left_thigh_pitch" multiplier="-1" offset="0" />
		</joint>
		<link name="parallel_left_knee_front_link">
			<visual>
				<origin xyz="0 0 0" rpy="0 0 0" />
				<geometry>
					<mesh filename="package://nimbro_op_model/mesh/nimbro_op2x_hull/knee_link.STL" />
				</geometry>
				<material name="white" />
			</visual>
		</link>

		<joint name="parallel_left_shank_pitch" type="continuous">
			<origin xyz="0 0 -0.1045" rpy="0 0 0" />
			<parent link="parallel_left_knee_front_link" />
			<child link="parallel_left_shank_front_link" />
			<axis xyz="0 1 0" />
		</joint>
		<link name="parallel_left_shank_front_link">
			<visual>
				<origin xyz="0 0 0" rpy="0 0 0" />
				<geometry>
					<mesh filename="package://nimbro_op_model/mesh/nimbro_op2x_hull/shank_front_link.STL" />
				</geometry>
				<material name="white" />
			</visual>
		</link>
		<joint name="parallel_left_shank_pitch_mimic1" type="continuous">
			<origin xyz="0 0 -0.26" rpy="0 0 0" />
			<parent link="parallel_left_shank_front_link" />
			<child link="parallel_left_ankle_link" />
			<axis xyz="0 1 0" />
			<mimic joint="parallel_left_shank_pitch" multiplier="-1" offset="0" />
		</joint>
		<link name="parallel_left_ankle_link">
			<visual>
				<origin xyz="-0.03345 0 0.0139" rpy="0 0 0" />
				<geometry>
					<mesh filename="package://nimbro_op_model/mesh/nimbro_op2x_hull/left_ankle_link.STL" />
				</geometry>
				<material name="white" />
			</visual>
		</link>
		<joint name="parallel_left_ankle_roll" type="continuous">
			<origin xyz="-0.03345 0 -0.01955" rpy="0 0 0" />
			<parent link="parallel_left_ankle_link" />
			<child link="parallel_left_foot_link" />
			<axis xyz="1 0 0" />
		</joint>
		<link name="parallel_left_foot_link">
			<visual>
				<origin xyz="0 0 0" rpy="0 0 0" />
				<geometry>
					<mesh filename="package://nimbro_op_model/mesh/nimbro_op2x_hull/left_foot_link.STL" />
				</geometry>
				<material name="white" />
			</visual>
		</link>
		<joint name="parallel_left_foot_plane_joint" type="fixed">
			<origin xyz="0.04562 0.005 -0.055" rpy="0 0 0" />
			<parent link="parallel_left_foot_link" />
			<child link="parallel_left_foot_plane_link" />
		</joint>
		<link name="parallel_left_foot_plane_link">
		</link>

		<!-- back chain-->

		<joint name="parallel_left_thigh_pitch_mimic2" type="continuous">
			<origin xyz="-0.036 0 -0.04755" rpy="0 0 0" />
			<parent link="left_hip_roll_link" />
			<child link="parallel_left_thigh_back_link" />
			<axis xyz="0 1 0" />
			<mimic joint="parallel_left_thigh_pitch" multiplier="1" offset="0" />
		</joint>
		<link name="parallel_left_thigh_back_link">
			<visual>
				<origin xyz="0 0 0" rpy="0 0 0" />
				<geometry>
					<mesh filename="package://nimbro_op_model/mesh/nimbro_op2x_hull/thigh_back_link.STL" />
				</geometry>
				<material name="white" />
			</visual>
		</link>
		<joint name="parallel_left_thigh_pitch_mimic3" type="continuous">
			<origin xyz="0 0 -0.26" rpy="0 0 0" />
			<parent link="parallel_left_thigh_back_link" />
			<child link="parallel_left_knee_back_link" />
			<axis xyz="0 1 0" />
			<mimic joint="parallel_left_thigh_pitch" multiplier="-1" offset="0" />
		</joint>
		<link name="parallel_left_knee_back_link">
		</link>

		<joint name="parallel_left_shank_pitch_mimic2" type="continuous">
			<origin xyz="0 0 -0.0485" rpy="0 0 0" />
			<parent link="parallel_left_knee_back_link" />
			<child link="parallel_left_shank_back_link" />
			<axis xyz="0 1 0" />
			<mimic joint="parallel_left_shank_pitch" multiplier="1" offset="0" />
		</joint>
		<link name="parallel_left_shank_back_link">
			<visual>
				<origin xyz="0 0 0" rpy="0 0 0" />
				<geometry>
					<mesh filename="package://nimbro_op_model/mesh/nimbro_op2x_hull/shank_back_link.STL" />
				</geometry>
				<material name="white" />
			</visual>
		</link>

		<!-- Transmissions -->
		<transmission name="right_hip_yaw_transmission">
			<type>transmission_interface/SimpleTransmission</type>
			<joint name="right_hip_yaw" >
                <hardwareInterface>EffortJointInterface</hardwareInterface>
            </joint>
			<actuator name="right_hip_yaw">
				<mechanicalReduction>1</mechanicalReduction>
			</actuator>
		</transmission>
		<transmission name="right_hip_roll_transmission">
			<type>transmission_interface/SimpleTransmission</type>
            <joint name="right_hip_roll" >
				<hardwareInterface>EffortJointInterface</hardwareInterface>
            </joint>
			<actuator name="right_hip_roll">
				<mechanicalReduction>1</mechanicalReduction>
			</actuator>
		</transmission>
		<transmission name="right_hip_pitch_transmission">
			<type>transmission_interface/SimpleTransmission</type>
            <joint name="right_hip_pitch" >
				<hardwareInterface>EffortJointInterface</hardwareInterface>
            </joint>
			<actuator name="right_hip_pitch">
				<mechanicalReduction>1</mechanicalReduction>
			</actuator>
		</transmission>
		<transmission name="right_knee_pitch_transmission">
			<type>transmission_interface/SimpleTransmission</type>
            <joint name="right_knee_pitch" >
				<hardwareInterface>EffortJointInterface</hardwareInterface>
            </joint>
			<actuator name="right_knee_pitch">
				<mechanicalReduction>1</mechanicalReduction>
			</actuator>
		</transmission>
		<transmission name="right_ankle_pitch_transmission">
			<type>transmission_interface/SimpleTransmission</type>
            <joint name="right_ankle_pitch" >
				<hardwareInterface>EffortJointInterface</hardwareInterface>
            </joint>
			<actuator name="right_ankle_pitch">
				<mechanicalReduction>1</mechanicalReduction>
			</actuator>
		</transmission>
		<transmission name="right_ankle_roll_transmission">
			<type>transmission_interface/SimpleTransmission</type>
            <joint name="right_ankle_roll" >
                <hardwareInterface>EffortJointInterface</hardwareInterface>
            </joint>
			<actuator name="right_ankle_roll">
				<mechanicalReduction>1</mechanicalReduction>
			</actuator>
		</transmission>
		<transmission name="left_hip_yaw_transmission">
			<type>transmission_interface/SimpleTransmission</type>
            <joint name="left_hip_yaw" >
				<hardwareInterface>EffortJointInterface</hardwareInterface>
            </joint>
			<actuator name="left_hip_yaw">
				<mechanicalReduction>1</mechanicalReduction>
			</actuator>
		</transmission>
		<transmission name="left_hip_roll_transmission">
			<type>transmission_interface/SimpleTransmission</type>
            <joint name="left_hip_roll" >
				<hardwareInterface>EffortJointInterface</hardwareInterface>
            </joint>
			<actuator name="left_hip_roll">
				<mechanicalReduction>1</mechanicalReduction>
			</actuator>
		</transmission>
		<transmission name="left_hip_pitch_transmission">
			<type>transmission_interface/SimpleTransmission</type>
            <joint name="left_hip_pitch" >
				<hardwareInterface>EffortJointInterface</hardwareInterface>
            </joint>
			<actuator name="left_hip_pitch">
				<mechanicalReduction>1</mechanicalReduction>
			</actuator>
		</transmission>
		<transmission name="left_knee_pitch_transmission">
			<type>transmission_interface/SimpleTransmission</type>
            <joint name="left_knee_pitch" >
				<hardwareInterface>EffortJointInterface</hardwareInterface>
            </joint>
			<actuator name="left_knee_pitch">
				<mechanicalReduction>1</mechanicalReduction>
			</actuator>
		</transmission>
		<transmission name="left_ankle_pitch_transmission">
			<type>transmission_interface/SimpleTransmission</type>
            <joint name="left_ankle_pitch" >
				<hardwareInterface>EffortJointInterface</hardwareInterface>
            </joint>
			<actuator name="left_ankle_pitch">
				<mechanicalReduction>1</mechanicalReduction>
			</actuator>
		</transmission>
		<transmission name="left_ankle_roll_transmission">
			<type>transmission_interface/SimpleTransmission</type>
            <joint name="left_ankle_roll" >
				<hardwareInterface>EffortJointInterface</hardwareInterface>
            </joint>
			<actuator name="left_ankle_roll">
				<mechanicalReduction>1</mechanicalReduction>
			</actuator>
		</transmission>
		<transmission name="right_shoulder_pitch_transmission">
			<type>transmission_interface/SimpleTransmission</type>
            <joint name="right_shoulder_pitch" >
				<hardwareInterface>EffortJointInterface</hardwareInterface>
            </joint>
			<actuator name="right_shoulder_pitch">
				<mechanicalReduction>1</mechanicalReduction>
			</actuator>
		</transmission>
		<transmission name="right_shoulder_roll_transmission">
			<type>transmission_interface/SimpleTransmission</type>
            <joint name="right_shoulder_roll" >
				<hardwareInterface>EffortJointInterface</hardwareInterface>
            </joint>
			<actuator name="right_shoulder_roll">
				<mechanicalReduction>1</mechanicalReduction>
			</actuator>
		</transmission>
		<transmission name="right_elbow_pitch_transmission">
			<type>transmission_interface/SimpleTransmission</type>
            <joint name="right_elbow_pitch" >
				<hardwareInterface>EffortJointInterface</hardwareInterface>
            </joint>
			<actuator name="right_elbow_pitch">
				<mechanicalReduction>1</mechanicalReduction>
			</actuator>
		</transmission>
		<transmission name="left_shoulder_pitch_transmission">
			<type>transmission_interface/SimpleTransmission</type>
            <joint name="left_shoulder_pitch" >
				<hardwareInterface>EffortJointInterface</hardwareInterface>
            </joint>
			<actuator name="left_shoulder_pitch">
				<mechanicalReduction>1</mechanicalReduction>
			</actuator>
		</transmission>
		<transmission name="left_shoulder_roll_transmission">
			<type>transmission_interface/SimpleTransmission</type>
            <joint name="left_shoulder_roll" >
				<hardwareInterface>EffortJointInterface</hardwareInterface>
            </joint>
			<actuator name="left_shoulder_roll">
				<mechanicalReduction>1</mechanicalReduction>
			</actuator>
		</transmission>
		<transmission name="left_elbow_pitch_transmission">
			<type>transmission_interface/SimpleTransmission</type>
            <joint name="left_elbow_pitch" >
				<hardwareInterface>EffortJointInterface</hardwareInterface>
            </joint>
			<actuator name="left_elbow_pitch">
				<mechanicalReduction>1</mechanicalReduction>
			</actuator>
		</transmission>
		<transmission name="neck_yaw_transmission">
			<type>transmission_interface/SimpleTransmission</type>
            <joint name="neck_yaw" >
				<hardwareInterface>EffortJointInterface</hardwareInterface>
            </joint>
			<actuator name="neck_yaw">
				<mechanicalReduction>1</mechanicalReduction>
			</actuator>
		</transmission>
		<transmission name="head_pitch_transmission">
			<type>transmission_interface/SimpleTransmission</type>
            <joint name="head_pitch" >
				<hardwareInterface>EffortJointInterface</hardwareInterface>
            </joint>
			<actuator name="head_pitch">
				<mechanicalReduction>1</mechanicalReduction>
			</actuator>
		</transmission>


		<!-- Gazebo configuration -->

		<gazebo>
			<plugin name="gazebo_ros_control" filename="libgazebo_ros_control.so">
				<robotNamespace>/nimbro_op</robotNamespace>
			</plugin>
		</gazebo>

		<!-- Gazebo links -->
		<gazebo reference="trunk_link">
			<material>Gazebo/White</material>
		</gazebo>
		<gazebo reference="left_hip_yaw_link">
			<material>Gazebo/White</material>
		</gazebo>
		<gazebo reference="left_hip_roll_link">
			<material>Gazebo/White</material>
		</gazebo>
		<gazebo reference="left_thigh_link">
			<material>Gazebo/White</material>
		</gazebo>
		<gazebo reference="left_shank_link">
			<material>Gazebo/White</material>
		</gazebo>
		<gazebo reference="left_ankle_link">
			<material>Gazebo/White</material>
		</gazebo>
		<gazebo reference="left_foot_link">
			<material>Gazebo/White</material>
			<kp>1000000.0</kp>
			<kd>100.0</kd>
			<mu1>1.0</mu1>
			<mu2>1.0</mu2>
			<fdir1>1 0 0</fdir1>
			<maxVel>1.0</maxVel>
			<minDepth>0.00</minDepth>
		</gazebo>
		<gazebo reference="left_shoulder_pitch_link">
			<material>Gazebo/White</material>
		</gazebo>
		<gazebo reference="left_upper_arm_link">
			<material>Gazebo/White</material>
		</gazebo>
		<gazebo reference="left_lower_arm_link">
			<material>Gazebo/White</material>
		</gazebo>
		<gazebo reference="right_hip_yaw_link">
			<material>Gazebo/White</material>
		</gazebo>
		<gazebo reference="right_hip_roll_link">
			<material>Gazebo/White</material>
		</gazebo>
		<gazebo reference="right_thigh_link">
			<material>Gazebo/White</material>
		</gazebo>
		<gazebo reference="right_shank_link">
			<material>Gazebo/White</material>
		</gazebo>
		<gazebo reference="right_ankle_link">
			<material>Gazebo/White</material>
		</gazebo>
		<gazebo reference="right_foot_link">
			<material>Gazebo/White</material>
			<kp>1000000.0</kp>
			<kd>100.0</kd>
			<mu1>1.0</mu1>
			<mu2>1.0</mu2>
			<fdir1>1 0 0</fdir1>
			<maxVel>1.0</maxVel>
			<minDepth>0.00</minDepth>
		</gazebo>
		<gazebo reference="right_shoulder_pitch_link">
			<material>Gazebo/White</material>
		</gazebo>
		<gazebo reference="right_upper_arm_link">
			<material>Gazebo/White</material>
		</gazebo>
		<gazebo reference="right_lower_arm_link">
			<material>Gazebo/White</material>
		</gazebo>
		<gazebo reference="neck_link">
			<material>Gazebo/Black</material>
		</gazebo>
</robot>
